[2022-07-17 08:32:20,629] [face01lib.Core] [Calc.py] [WARNING] 試用期限を過ぎました
[2022-07-17 08:32:20,630] [face01lib.Core] [Calc.py] [WARNING] 引き続きご利用になる場合は下記までご連絡下さい
[2022-07-17 08:35:22,000] [face01lib.Core] [Calc.py] [WARNING] 試用期限を過ぎました
[2022-07-17 08:35:22,000] [face01lib.Core] [Calc.py] [WARNING] 引き続きご利用になる場合は下記までご連絡下さい
[2022-07-17 08:36:57,986] [face01lib.Core] [Calc.py] [WARNING] 試用期限を過ぎました
[2022-07-17 08:36:57,986] [face01lib.Core] [Calc.py] [WARNING] 引き続きご利用になる場合は下記までご連絡下さい
[2022-07-17 08:40:23,734] [face01lib.Core] [Calc.py] [WARNING] 試用期限を過ぎました
[2022-07-17 08:40:23,734] [face01lib.Core] [Calc.py] [WARNING] 引き続きご利用になる場合は下記までご連絡下さい
[2022-07-17 08:40:23,735] [face01lib.Core] [Calc.py] [WARNING] 東海顔認証　担当：袈裟丸 y.kesamaru@tokai-kaoninsho.com
[2022-07-17 08:40:56,632] [face01lib.Core] [Calc.py] [WARNING] 試用期限を過ぎました
[2022-07-17 08:40:56,632] [face01lib.Core] [Calc.py] [WARNING] 引き続きご利用になる場合は下記までご連絡下さい
[2022-07-17 08:40:56,633] [face01lib.Core] [Calc.py] [WARNING] 東海顔認証　担当：袈裟丸 y.kesamaru@tokai-kaoninsho.com
[2022-07-17 08:41:56,474] [face01lib.Core] [Calc.py] [WARNING] 試用期限を過ぎました
[2022-07-17 08:41:56,474] [face01lib.Core] [Calc.py] [WARNING] 引き続きご利用になる場合は下記までご連絡下さい
[2022-07-17 08:41:56,474] [face01lib.Core] [Calc.py] [WARNING] 東海顔認証 担当: 袈裟丸 y.kesamaru@tokai-kaoninsho.com
[2022-07-17 08:42:09,904] [face01lib.Core] [Calc.py] [WARNING] 試用期限を過ぎました
[2022-07-17 08:42:09,904] [face01lib.Core] [Calc.py] [WARNING] 引き続きご利用になる場合は下記までご連絡下さい
[2022-07-17 08:42:09,905] [face01lib.Core] [Calc.py] [WARNING] 東海顔認証 担当: 袈裟丸 y.kesamaru@tokai-kaoninsho.com
[2022-07-17 08:42:22,403] [face01lib.Core] [Calc.py] [WARNING] 試用期限を過ぎました
[2022-07-17 08:42:22,404] [face01lib.Core] [Calc.py] [WARNING] 引き続きご利用になる場合は下記までご連絡下さい
[2022-07-17 08:42:22,404] [face01lib.Core] [Calc.py] [WARNING] 東海顔認証 担当: 袈裟丸 y.kesamaru@tokai-kaoninsho.com
[2022-07-17 15:45:06,967] [face01lib.video_capture] [video_capture.py] [WARNING] 以下のエラーをシステム管理者へお伝えください
[2022-07-17 15:45:06,968] [face01lib.video_capture] [video_capture.py] [WARNING] --------------------
[2022-07-17 15:45:06,969] [face01lib.video_capture] [video_capture.py] [WARNING] Traceback (most recent call last):
  File "/home/terms/bin/FACE01/face01lib/video_capture.py", line 222, in frame_generator
    frame  = cv2.cvtColor(img_np, cv2.COLOR_RGBA2BGR)
NameError: name 'cv2' is not defined

[2022-07-17 15:45:06,970] [face01lib.video_capture] [video_capture.py] [ERROR] 通信に異常が発生しました
Traceback (most recent call last):
  File "/home/terms/bin/FACE01/face01lib/video_capture.py", line 222, in frame_generator
    frame  = cv2.cvtColor(img_np, cv2.COLOR_RGBA2BGR)
NameError: name 'cv2' is not defined
[2022-07-17 15:45:06,971] [face01lib.video_capture] [video_capture.py] [WARNING] --------------------
[2022-07-17 15:45:06,971] [face01lib.video_capture] [video_capture.py] [WARNING] 終了します
[2022-07-17 16:15:59,597] [face01lib.video_capture] [video_capture.py] [WARNING] 以下のエラーをシステム管理者へお伝えください
[2022-07-17 16:15:59,597] [face01lib.video_capture] [video_capture.py] [WARNING] --------------------
[2022-07-17 16:15:59,598] [face01lib.video_capture] [video_capture.py] [WARNING] Traceback (most recent call last):
  File "/home/terms/bin/FACE01/face01lib/video_capture.py", line 219, in frame_generator
    if response.headers['Content-type'] == 'image/jpeg':
UnboundLocalError: local variable 'response' referenced before assignment

[2022-07-17 16:15:59,598] [face01lib.video_capture] [video_capture.py] [ERROR] 通信に異常が発生しました
Traceback (most recent call last):
  File "/home/terms/bin/FACE01/face01lib/video_capture.py", line 219, in frame_generator
    if response.headers['Content-type'] == 'image/jpeg':
UnboundLocalError: local variable 'response' referenced before assignment
[2022-07-17 16:15:59,599] [face01lib.video_capture] [video_capture.py] [WARNING] --------------------
[2022-07-17 16:15:59,599] [face01lib.video_capture] [video_capture.py] [WARNING] 終了します
[2022-07-17 16:16:43,156] [face01lib.video_capture] [video_capture.py] [WARNING] 以下のエラーをシステム管理者へお伝えください
[2022-07-17 16:16:43,157] [face01lib.video_capture] [video_capture.py] [WARNING] --------------------
[2022-07-17 16:16:43,157] [face01lib.video_capture] [video_capture.py] [WARNING] Traceback (most recent call last):
  File "/home/terms/bin/FACE01/face01lib/video_capture.py", line 219, in frame_generator
    if response.headers['Content-type'] == 'image/jpeg':
UnboundLocalError: local variable 'response' referenced before assignment

[2022-07-17 16:16:43,158] [face01lib.video_capture] [video_capture.py] [ERROR] 通信に異常が発生しました
Traceback (most recent call last):
  File "/home/terms/bin/FACE01/face01lib/video_capture.py", line 219, in frame_generator
    if response.headers['Content-type'] == 'image/jpeg':
UnboundLocalError: local variable 'response' referenced before assignment
[2022-07-17 16:16:43,158] [face01lib.video_capture] [video_capture.py] [WARNING] --------------------
[2022-07-17 16:16:43,158] [face01lib.video_capture] [video_capture.py] [WARNING] 終了します
[2022-07-17 16:17:54,223] [face01lib.video_capture] [video_capture.py] [WARNING] 以下のエラーをシステム管理者へお伝えください
[2022-07-17 16:17:54,223] [face01lib.video_capture] [video_capture.py] [WARNING] --------------------
[2022-07-17 16:17:54,225] [face01lib.video_capture] [video_capture.py] [WARNING] Traceback (most recent call last):
  File "/home/terms/bin/FACE01/face01lib/video_capture.py", line 219, in frame_generator
    if response.headers['Content-type'] == 'image/jpeg':
UnboundLocalError: local variable 'response' referenced before assignment

[2022-07-17 16:17:54,225] [face01lib.video_capture] [video_capture.py] [ERROR] 通信に異常が発生しました
Traceback (most recent call last):
  File "/home/terms/bin/FACE01/face01lib/video_capture.py", line 219, in frame_generator
    if response.headers['Content-type'] == 'image/jpeg':
UnboundLocalError: local variable 'response' referenced before assignment
[2022-07-17 16:17:54,226] [face01lib.video_capture] [video_capture.py] [WARNING] --------------------
[2022-07-17 16:17:54,226] [face01lib.video_capture] [video_capture.py] [WARNING] 終了します
[2022-07-17 16:19:02,765] [face01lib.video_capture] [video_capture.py] [WARNING] 以下のエラーをシステム管理者へお伝えください
[2022-07-17 16:19:02,766] [face01lib.video_capture] [video_capture.py] [WARNING] --------------------
[2022-07-17 16:19:02,767] [face01lib.video_capture] [video_capture.py] [WARNING] Traceback (most recent call last):
  File "/home/terms/bin/FACE01/face01lib/video_capture.py", line 219, in frame_generator
    if response.headers['Content-type'] == 'image/jpeg':
UnboundLocalError: local variable 'response' referenced before assignment

[2022-07-17 16:19:02,767] [face01lib.video_capture] [video_capture.py] [ERROR] 通信に異常が発生しました
Traceback (most recent call last):
  File "/home/terms/bin/FACE01/face01lib/video_capture.py", line 219, in frame_generator
    if response.headers['Content-type'] == 'image/jpeg':
UnboundLocalError: local variable 'response' referenced before assignment
[2022-07-17 16:19:02,768] [face01lib.video_capture] [video_capture.py] [WARNING] --------------------
[2022-07-17 16:19:02,768] [face01lib.video_capture] [video_capture.py] [WARNING] 終了します
[2022-07-24 18:47:25,949] [face01lib.video_capture] [video_capture.py] [WARNING] USBカメラの受信が出来ません
[2022-07-24 18:47:25,963] [face01lib.video_capture] [video_capture.py] [WARNING] 以下のエラーをシステム管理者へお伝えください
[2022-07-24 18:47:25,963] [face01lib.video_capture] [video_capture.py] [WARNING] --------------------
[2022-07-24 18:47:25,964] [face01lib.video_capture] [video_capture.py] [WARNING] NoneType: None

[2022-07-24 18:47:25,964] [face01lib.video_capture] [video_capture.py] [ERROR] USBカメラとの通信に異常が発生しました
NoneType: None
[2022-07-24 18:47:25,965] [face01lib.video_capture] [video_capture.py] [WARNING] --------------------
[2022-07-24 18:47:25,965] [face01lib.video_capture] [video_capture.py] [WARNING] 終了します
[2022-07-31 07:29:55,148] [face01lib.video_capture] [video_capture.py] [WARNING] USBカメラの受信が出来ません
[2022-07-31 07:29:55,148] [face01lib.video_capture] [video_capture.py] [WARNING] 以下のエラーをシステム管理者へお伝えください
[2022-07-31 07:29:55,149] [face01lib.video_capture] [video_capture.py] [WARNING] --------------------
[2022-07-31 07:29:55,150] [face01lib.video_capture] [video_capture.py] [WARNING] NoneType: None

[2022-07-31 07:29:55,151] [face01lib.video_capture] [video_capture.py] [ERROR] USBカメラとの通信に異常が発生しました
NoneType: None
[2022-07-31 07:29:55,152] [face01lib.video_capture] [video_capture.py] [WARNING] --------------------
[2022-07-31 07:29:55,153] [face01lib.video_capture] [video_capture.py] [WARNING] 終了します
[2022-08-01 09:23:09,963] [face01lib.video_capture] [video_capture.py] [WARNING] 受信できません
[2022-08-01 09:23:09,964] [face01lib.video_capture] [video_capture.py] [WARNING] --------------------
[2022-08-01 09:23:09,965] [face01lib.video_capture] [video_capture.py] [WARNING] NoneType: None

[2022-08-01 09:23:09,966] [face01lib.video_capture] [video_capture.py] [WARNING] --------------------
[2022-08-01 09:23:09,966] [face01lib.video_capture] [video_capture.py] [WARNING] 終了します
[2022-08-01 09:24:07,149] [face01lib.video_capture] [video_capture.py] [WARNING] 受信できません
[2022-08-01 09:24:07,150] [face01lib.video_capture] [video_capture.py] [WARNING] --------------------
[2022-08-01 09:24:07,151] [face01lib.video_capture] [video_capture.py] [WARNING] NoneType: None

[2022-08-01 09:24:07,152] [face01lib.video_capture] [video_capture.py] [WARNING] --------------------
[2022-08-01 09:24:07,153] [face01lib.video_capture] [video_capture.py] [WARNING] 終了します
[2022-08-01 09:25:01,320] [face01lib.video_capture] [video_capture.py] [WARNING] 受信できません
[2022-08-01 09:25:02,255] [face01lib.video_capture] [video_capture.py] [WARNING] --------------------
[2022-08-01 09:25:03,111] [face01lib.video_capture] [video_capture.py] [WARNING] NoneType: None

[2022-08-01 09:25:04,984] [face01lib.video_capture] [video_capture.py] [WARNING] --------------------
[2022-08-01 09:25:05,599] [face01lib.video_capture] [video_capture.py] [WARNING] 終了します
[2022-08-01 09:31:43,676] [face01lib.video_capture] [video_capture.py] [INFO] カメラデバイス番号：-5
[2022-08-01 09:34:19,515] [face01lib.video_capture] [video_capture.py] [INFO] カメラデバイス番号：-5
[2022-08-01 17:27:53,915] [face01lib.video_capture] [video_capture.py] [WARNING] USBカメラの受信が出来ません
[2022-08-01 17:27:53,915] [face01lib.video_capture] [video_capture.py] [WARNING] 以下のエラーをシステム管理者へお伝えください
[2022-08-01 17:27:53,916] [face01lib.video_capture] [video_capture.py] [WARNING] --------------------
[2022-08-01 17:27:53,916] [face01lib.video_capture] [video_capture.py] [WARNING] NoneType: None

[2022-08-01 17:27:53,917] [face01lib.video_capture] [video_capture.py] [ERROR] USBカメラとの通信に異常が発生しました
NoneType: None
[2022-08-01 17:27:53,917] [face01lib.video_capture] [video_capture.py] [WARNING] --------------------
[2022-08-01 17:27:53,918] [face01lib.video_capture] [video_capture.py] [WARNING] 終了します
[2022-08-01 17:28:16,881] [face01lib.video_capture] [video_capture.py] [WARNING] USBカメラの受信が出来ません
[2022-08-01 17:28:16,882] [face01lib.video_capture] [video_capture.py] [WARNING] 以下のエラーをシステム管理者へお伝えください
[2022-08-01 17:28:16,882] [face01lib.video_capture] [video_capture.py] [WARNING] --------------------
[2022-08-01 17:28:16,882] [face01lib.video_capture] [video_capture.py] [WARNING] NoneType: None

[2022-08-01 17:28:16,883] [face01lib.video_capture] [video_capture.py] [ERROR] USBカメラとの通信に異常が発生しました
NoneType: None
[2022-08-01 17:28:16,884] [face01lib.video_capture] [video_capture.py] [WARNING] --------------------
[2022-08-01 17:28:16,884] [face01lib.video_capture] [video_capture.py] [WARNING] 終了します
[2022-08-01 17:29:50,928] [face01lib.video_capture] [video_capture.py] [INFO] カメラデバイス番号：-5
[2022-08-01 17:34:01,928] [face01lib.video_capture] [video_capture.py] [INFO] カメラデバイス番号：-5
[2022-08-01 17:48:47,624] [face01lib.video_capture] [video_capture.py] [INFO] カメラデバイス番号：0
[2022-08-01 17:52:16,619] [face01lib.video_capture] [video_capture.py] [INFO] カメラデバイス番号：0
[2022-08-01 17:52:37,579] [face01lib.video_capture] [video_capture.py] [INFO] カメラデバイス番号：0
[2022-08-01 17:54:54,528] [face01lib.video_capture] [video_capture.py] [INFO] カメラデバイス番号：0
[2022-08-01 17:55:48,114] [face01lib.video_capture] [video_capture.py] [INFO] カメラデバイス番号：0
[2022-08-01 17:56:16,516] [face01lib.video_capture] [video_capture.py] [INFO] カメラデバイス番号：0
